<?xml version="1.0" encoding="UTF-8"?>
<testsuite errors="2" failures="1" file="authentication_route_tests.py" name="authentication_route_tests.AccountRouteTest-20200412170648" skipped="0" tests="7" time="0.026" timestamp="2020-04-12T17:06:48">
	<testcase classname="authentication_route_tests.AccountRouteTest" file="src\unittest\python\authentication_route_tests.py" line="32" name="test_authenticate_user_invalid_credentials_data" time="0.002" timestamp="2020-04-12T17:06:48">
		<system-out>
<![CDATA[]]>		</system-out>
		<system-err>
<![CDATA[]]>		</system-err>
	</testcase>
	<testcase classname="authentication_route_tests.AccountRouteTest" file="src\unittest\python\authentication_route_tests.py" line="42" name="test_authenticate_user_with_credentials_not_found" time="0.003" timestamp="2020-04-12T17:06:48">
		<system-out>
<![CDATA[]]>		</system-out>
		<system-err>
<![CDATA[]]>		</system-err>
	</testcase>
	<testcase classname="authentication_route_tests.AccountRouteTest" file="src\unittest\python\authentication_route_tests.py" line="25" name="test_authenticate_user_with_missing_fields" time="0.001" timestamp="2020-04-12T17:06:48">
		<system-out>
<![CDATA[]]>		</system-out>
		<system-err>
<![CDATA[]]>		</system-err>
	</testcase>
	<testcase classname="authentication_route_tests.AccountRouteTest" file="src\unittest\python\authentication_route_tests.py" line="62" name="test_token_protected_with_no_authorization_headers" time="0.002" timestamp="2020-04-12T17:06:48">
		<system-out>
<![CDATA[]]>		</system-out>
		<system-err>
<![CDATA[]]>		</system-err>
	</testcase>
	<testcase classname="authentication_route_tests.AccountRouteTest" file="src\unittest\python\authentication_route_tests.py" line="52" name="test_authenticate_user_with_credentials_found" time="0.018" timestamp="2020-04-12T17:06:48">
		<failure message="'successfuly authenticated' not found in '&lt;!DOCTYPE HTML PUBLIC &quot;-//W3C//DTD HTML 3.2 Final//EN&quot;&gt;\n&lt;title&gt;500 Internal Server Error&lt;/title&gt;\n&lt;h1&gt;Internal Server Error&lt;/h1&gt;\n&lt;p&gt;The server encountered an internal error and was unable to complete your request. Either the server is overloaded or there is an error in the application.&lt;/p&gt;\n'" type="AssertionError">
<![CDATA[Traceback (most recent call last):
  File "c:\users\michael\appdata\local\programs\python\python36\lib\unittest\mock.py", line 1183, in patched
    return func(*args, **keywargs)
  File "c:\users\michael\desktop\soft_eng\project\ecommerce_site\backend\src\unittest\python\authentication_route_tests.py", line 59, in test_authenticate_user_with_credentials_found
    self.assertIn("successfuly authenticated", result)
AssertionError: 'successfuly authenticated' not found in '<!DOCTYPE HTML PUBLIC "-//W3C//DTD HTML 3.2 Final//EN">\n<title>500 Internal Server Error</title>\n<h1>Internal Server Error</h1>\n<p>The server encountered an internal error and was unable to complete your request. Either the server is overloaded or there is an error in the application.</p>\n'
]]>		</failure>
		<system-out>
<![CDATA[]]>		</system-out>
		<system-err>
<![CDATA[[2020-04-12 17:06:48,542] ERROR in app: Exception on /api/auth [POST]
Traceback (most recent call last):
  File "C:\Users\Michael\Desktop\soft_eng\project\ecommerce_site\venv\lib\site-packages\flask\app.py", line 2446, in wsgi_app
    response = self.full_dispatch_request()
  File "C:\Users\Michael\Desktop\soft_eng\project\ecommerce_site\venv\lib\site-packages\flask\app.py", line 1951, in full_dispatch_request
    rv = self.handle_user_exception(e)
  File "C:\Users\Michael\Desktop\soft_eng\project\ecommerce_site\venv\lib\site-packages\flask_cors\extension.py", line 161, in wrapped_function
    return cors_after_request(app.make_response(f(*args, **kwargs)))
  File "C:\Users\Michael\Desktop\soft_eng\project\ecommerce_site\venv\lib\site-packages\flask\app.py", line 1820, in handle_user_exception
    reraise(exc_type, exc_value, tb)
  File "C:\Users\Michael\Desktop\soft_eng\project\ecommerce_site\venv\lib\site-packages\flask\_compat.py", line 39, in reraise
    raise value
  File "C:\Users\Michael\Desktop\soft_eng\project\ecommerce_site\venv\lib\site-packages\flask\app.py", line 1949, in full_dispatch_request
    rv = self.dispatch_request()
  File "C:\Users\Michael\Desktop\soft_eng\project\ecommerce_site\venv\lib\site-packages\flask\app.py", line 1935, in dispatch_request
    return self.view_functions[rule.endpoint](**req.view_args)
  File "src\main\python\app.py", line 106, in authenticate_user
    token = jwt.encode(
AttributeError: module 'jwt' has no attribute 'encode'
]]>		</system-err>
	</testcase>
	<testcase classname="authentication_route_tests.AccountRouteTest" file="src\unittest\python\authentication_route_tests.py" line="68" name="test_token_protected_with_invalid_token" time="0.000" timestamp="2020-04-12T17:06:48">
		<error message="&lt;module 'jwt' from 'C:\\Users\\Michael\\Desktop\\soft_eng\\project\\ecommerce_site\\venv\\lib\\site-packages\\jwt\\__init__.py'&gt; does not have the attribute 'decode'" type="AttributeError">
<![CDATA[Traceback (most recent call last):
  File "c:\users\michael\appdata\local\programs\python\python36\lib\unittest\mock.py", line 1175, in patched
    arg = patching.__enter__()
  File "c:\users\michael\appdata\local\programs\python\python36\lib\unittest\mock.py", line 1247, in __enter__
    original, local = self.get_original()
  File "c:\users\michael\appdata\local\programs\python\python36\lib\unittest\mock.py", line 1221, in get_original
    "%s does not have the attribute %r" % (target, name)
AttributeError: <module 'jwt' from 'C:\\Users\\Michael\\Desktop\\soft_eng\\project\\ecommerce_site\\venv\\lib\\site-packages\\jwt\\__init__.py'> does not have the attribute 'decode'
]]>		</error>
		<system-out>
<![CDATA[]]>		</system-out>
		<system-err>
<![CDATA[]]>		</system-err>
	</testcase>
	<testcase classname="authentication_route_tests.AccountRouteTest" file="src\unittest\python\authentication_route_tests.py" line="78" name="test_token_protected_with_valid_token" time="0.000" timestamp="2020-04-12T17:06:48">
		<error message="&lt;module 'jwt' from 'C:\\Users\\Michael\\Desktop\\soft_eng\\project\\ecommerce_site\\venv\\lib\\site-packages\\jwt\\__init__.py'&gt; does not have the attribute 'decode'" type="AttributeError">
<![CDATA[Traceback (most recent call last):
  File "c:\users\michael\appdata\local\programs\python\python36\lib\unittest\mock.py", line 1175, in patched
    arg = patching.__enter__()
  File "c:\users\michael\appdata\local\programs\python\python36\lib\unittest\mock.py", line 1247, in __enter__
    original, local = self.get_original()
  File "c:\users\michael\appdata\local\programs\python\python36\lib\unittest\mock.py", line 1221, in get_original
    "%s does not have the attribute %r" % (target, name)
AttributeError: <module 'jwt' from 'C:\\Users\\Michael\\Desktop\\soft_eng\\project\\ecommerce_site\\venv\\lib\\site-packages\\jwt\\__init__.py'> does not have the attribute 'decode'
]]>		</error>
		<system-out>
<![CDATA[]]>		</system-out>
		<system-err>
<![CDATA[]]>		</system-err>
	</testcase>
</testsuite>
